Workbook

Sheet ORDINI EVASI (3)
A1: ORDINI ELTHUB - EVASI
E2: =SUM(E6:E1318) -> 4366334.2 | F2: =SUM(F6:F1318) -> -0.0097 | G2: =SUM(G6:G1318) -> 4366334.2 | N2: VALUTA CAMBIO USD AL 31/03/2025: | O2: 0.93
N3: VALUTA CAMBIO GBP AL 31/08/2025: | O3: 1.15 | Q3: =SUM(Q6:Q1347) -> 130967.16 | R3: =SUM(R6:R1347) -> 131366.78 | S3: =SUM(S6:S1347) -> 159104.8 | T3: =SUM(T6:T1347) -> 368481.16 | U3: =SUM(U6:U1347) -> 195029.63 | V3: =SUM(V6:V1347) -> 434341.94 | W3: =SUM(W6:W1347) -> 181121.12 | X3: =SUM(X6:X1347) -> 260363.98 | ... AE3: =SUM(AE6:AE1347) -> 0
A5: OPERATORE | B5: NUMERO | C5: DATA | D5: FORNITORE | E5: IMPORTO TOTALE | F5: IMP. TOT. DA EVADERE | G5: IMP. TOT. EVASO | H5: DATA RICHIESTA | I5: DATA CONFERMAYA | J5: DATA EFFETTIVA | K5: JOB / CDC | L5: STATO | M5: CONFERMA | N5: NOTE | O5: VALUTA USD | P5: VALUTA GBP | Q5: MARZO | R5: APRILE | S5: MAGGIO | T5: GIUGNO | U5: LUGLIO | V5: AGOSTO | W5: SETTEMBRE | X5: OTTOBRE | Y5: NOVEMBRE | Z5: DICEMBRE | AA5: GENNAIO 2026 | AB5: FEBBRAIO 2026 | AC5: MARZO 2026 | AD5: APRILE 2026 | AE5: MAGGIO 2026
B6: 38 | C6: 45309 | D6: METATRON | E6: 165 | F6: =E6-G6 -> 0 | G6: 165 | K6: E-00071 (LCTE) | L6: EVASO
B7: 41 | C7: 45313 | D7: PONTECORVO | E7: 263.26 | F7: =E7-G7 -> 0 | G7: 263.26 | K7: E-00067 (EWE) | L7: EVASO
B8: 42 | C8: 45313 | D8: PONTECORVO | E8: 454.92 | F8: =E8-G8 -> 0 | G8: 454.92 | K8: E-00083 (PANALYTICAL) | L8: EVASO
B9: 44 | C9: 45313 | D9: PONTECORVO | E9: 89.32 | F9: =E9-G9 -> 0 | G9: 89.32 | K9: E-00091 (GOMA) | L9: EVASO
B10: 45 | C10: 45313 | D10: FARNELL | E10: 77.88 | F10: =E10-G10 -> 0 | G10: 77.88 | K10: E-00094 (PANALYTICAL) | L10: EVASO
B11: 414 | C11: 45278 | D11: AIR SERVICE | E11: 570 | F11: =E11-G11 -> 0 | G11: 570 | K11: CDC-07/40 (DIR STAB/MANUT IMPIANTI) | L11: EVASO
B12: 432 | C12: 45288 | D12: MOUSER | E12: 2420.86 | F12: =E12-G12 -> 0 | G12: 2420.86 | K12: E-00067 (EWE) | L12: EVASO
B13: 7 | C13: 45303 | D13: MONDOFFICE | E13: 1213.87 | F13: =E13-G13 -> 0 | G13: 1213.87 | K13: CDC-7/34 | L13: EVASO
B14: 11 | C14: 45300 | D14: DB ELECTRONIC | E14: 4543.01 | F14: =E14-G14 -> 0 | G14: 4543.01 | K14: E-00079 (QUIRIS) | L14: EVASO
B15: 419 | C15: 45279 | D15: LA NUOVA EUROGALV | E15: 445.4 | F15: =E15-G15 -> 0 | G15: 445.4 | K15: E-00083 (PANALYTICAL) | L15: EVASO
B16: 427 | C16: 45282 | D16: ELCO | E16: 5055 | F16: =E16-G16 -> 0 | G16: 5055 | H16: 45320 | K16: E-00067 (EWE) | L16: EVASO | M16: SCRITTA
B17: 36 | C17: 45309 | D17: LA NUOVA EUROGALV | E17: 115.5 | F17: =E17-G17 -> 0 | G17: 115.5 | H17: 45322 | K17: E-00091 (GOMA) | L17: EVASO
B18: 47 | C18: 45315 | D18: RS COMPONENTS | E18: 81.85 | F18: =E18-G18 -> 0 | G18: 81.85 | H18: 45321 | K18: I-P0001 (NUTRI 3D) | L18: EVASO | M18: SCRITTA
B19: 49 | C19: 45317 | D19: MOUSER | E19: 227.57 | F19: =E19-G19 -> 0 | G19: 227.57 | H19: 45322 | K19: E-00071 (LCTE) | L19: CONFERMATO | M19: SCRITTA
B20: 16 | C20: 45301 | D20: GLV TECHNOLOGY | E20: 1800 | F20: =E20-G20 -> 0 | G20: 1800 | H20: 45322 | K20: CDC-5/17 (PROD/CONSULENZE) | L20: CONFERMATO | M20: VERBALE
B21: 56 | C21: 45321 | D21: RS COMPONENTS | E21: 110.34 | F21: =E21-G21 -> 0 | G21: 110.34 | H21: 45323 | K21: AUDIO ASSY | L21: CONFERMATO | M21: SCRITTA
B22: 54 | C22: 45321 | D22: FARNELL | E22: 382.52 | F22: =E22-G22 -> 0 | G22: 382.52 | H22: 45323 | K22: AUDIO ASSY | L22: CONFERMATO | M22: SCRITTA
B23: 415 | C23: 45279 | D23: SOLYNX | E23: =O23*O2 -> 1186.5312 | F23: =E23-G23 -> 0.0012 | G23: 1186.53 | H23: 45310 | K23: ELT 4500062051 | L23: INVIATO | M23: SCRITTA | N23: ORDINE EMESSO IN VALUTA USD | O23: 1275.84
B24: 23 | C24: 45303 | D24: QUASER | E24: 1321 | F24: =E24-G24 -> 0 | G24: 1321 | H24: 44966 | K24: INVESTIMENTO | L24: CONS. PARZ. | M24: SCRITTA
B25: 60 | C25: 45322 | D25: RS COMPONENTS | E25: 48.36 | F25: =E25-G25 -> 0 | G25: 48.36 | H25: 45324 | K25: E-00083 (PANALYTICAL) | L25: INVIATO | M25: SCRITTA
B26: 3 | C26: 45299 | D26: ELCO | E26: 1311 | F26: =E26-G26 -> 0 | G26: 1311 | H26: 45306 | K26: E-00079 (QUIRIS) | L26: CONFERMATO | M26: SCRITTA
B27: 59 | C27: 45322 | D27: PROVAL SERVICE | E27: 90.86 | F27: =E27-G27 -> 0 | G27: 90.86 | H27: 45324 | K27: E-00079 (QUIRIS) | L27: CONFERMATO | M27: SCRITTA
B28: 65 | C28: 45324 | D28: CECASA | E28: 3120 | F28: =E28-G28 -> 0 | G28: 3120 | H28: 45324 | K28: E-00071 (LCTE) | L28: CONFERMATO | M28: VERBALE
B29: 50 | C29: 45317 | D29: LA NUOVA EUROGALV | E29: 145 | F29: =E29-G29 -> 0 | G29: 145 | H29: 45327 | K29: E-00091 (GOMA) | L29: CONFERMATO | M29: SCRITTA
B30: 343 | C30: 45251 | D30: AVIATRONIK | E30: 3450 | F30: =E30-G30 -> 0 | G30: 3450 | H30: 45336 | K30: CDC 5/21 (PROD/MANUT. STRUMENTI) | L30: INVIATO
B31: 2 | C31: 45320 | D31: PF ELETTRONICA | E31: 2080 | F31: =E31-G31 -> 0 | G31: 2080 | H31: 45327 | K31: E-00067 (EWE) | L31: INVIATO
B32: 73 | C32: 45328 | D32: STAMPA E TAGLIO | E32: 45 | F32: =E32-G32 -> 0 | G32: 45 | H32: 45328 | K32: E-00083 (PANALYTICAL) | L32: INVIATO
B33: 69 | C33: 45327 | D33: GCI | E33: 84 | F33: =E33-G33 -> 0 | G33: 84 | H33: 45334 | K33: CDC-11/54 (INF. TECH/SPESE HARDWARE) | L33: CONFERMATO | M33: SCRITTA
B34: 230 | C34: 45204 | D34: OFFICINE LAMERA | E34: 62000 | F34: =E34-G34 -> 0 | G34: 62000 | H34: 45260 | K34: I-P0001 (INIZIALE QUIRIS) | L34: CONS. PARZ.
B35: 68 | C35: 45327 | D35: MONDOFFICE | E35: 239 | F35: =E35-G35 -> 0 | G35: 239 | H35: 45334 | K35: CDC-11/54 (INF. TECH/SPESE HARDWARE) | L35: CONFERMATO | M35: SCRITTA
B36: 57 | C36: 45321 | D36: LA NUOVA EUROGALV | E36: 400 | F36: =E36-G36 -> 0 | G36: 400 | H36: 45329 | K36: E-00079 (QUIRIS) | L36: CONFERMATO | M36: VERBALE
B37: 10 | C37: 45300 | D37: GCI | E37: 1460 | F37: =E37-G37 -> 0 | G37: 1460 | H37: 45310 | K37: CDC-11/55 (INF. TECH/LIC. SOFTWARE) | L37: EVASO | M37: SCRITTA
B38: 37 | C38: 45308 | D38: LA NUOVA EUROGALV | E38: 833.4 | F38: =E38-G38 -> 0 | G38: 833.4 | H38: 45322 | K38: E-00067 (EWE) | L38: CONS. PARZ. | M38: SCRITTA
B39: 84 | C39: 45330 | D39: TECNOMILL | E39: 135 | F39: =E39-G39 -> 0 | G39: 135 | H39: 45334 | K39: CDC-5/18 (DIR PROD/MAT PROTITIPI) | L39: CONFERMATO | M39: SCRITTA
B40: 40 | C40: 45313 | D40: ASSELTECH | E40: 185 | F40: =E40-G40 -> 0 | G40: 185 | H40: 45324 | K40: E-00067 (EWE) | L40: CONFERMATO | M40: SCRITTA
B41: 58 | C41: 45321 | D41: ASSELTECH | E41: 185 | F41: =E41-G41 -> 0 | G41: 185 | H41: 45324 | K41: E-00091 (GOMA) | L41: INVIATO | M41: SCRITTA
...

Sheet CLASSE A (progettazione)
D1: REGISTRO FORNITORI QUALIFICATI TIPO A - ITEM E SERVIZI AL CLIENTE
L2: Certificato disponibile
L3: Certificazione verificata di web
L4: Certificazione verificata Accredia
L5: Certificazione scaduta - richiedere nuova
B7: POS. | C7: TIPO | D7: RAGIONE SOCIALE | E7: TIPO | F7: AMBITO DI FORNITURA | G7: CERTIFICAZIONE | H7: DISTRIBUTORE UFFICIALE O BROKER | I7: NOTE | J7: KPI QUALITA' | K7: KPI TEMPI | L7: CERTIFICAZIONI | M7: DATA SCADENZA CERTIFICAZIONE | N7: DATA INSERIMENTO | O7: INVIO CGA | P7: ACCETTAZIONE | Q7: NON ACCETTAZIONE
B8: 1 | C8: A | D8: D & P Electronic Systems Srl | E8: FORNITORE A SPECIFICA | F8: PROGETTAZIONE HW/SW, SVILUPPO DOCUMENTAZIONE E FORNITURA SCHEDE DIGITALI | L8: ISO 9001:2015 - certificato n. 12963
B9: 2 | C9: A | D9: PARIANI S.R.L. | E9: COSTRUTTORE | F9: SISTEMI DI ILLUMINAZIONE | L9: ISO 9001:2015 | M9: 45538 | O9: SI
B10: 3 | C10: A | D10: TECNOTTICA CONSONNI S.R.L. | E10: COSTRUTTORE | F10: COMPONENTI PER SISTEMI OTTICI | L10: ISO 9001:2015 | M10: 46221 | N10: 45404 | O10: SI | P10: SI
B11: 4 | C11: A | D11: ACX DESIGN S.R.L. | E11: COSTRUTTORE | F11: COSTRUTTORE CIRCUITI STAMPATI | L11: ISO 9001:2015 | M11: 46876 | N11: 45411
B12: 5 | C12: A | D12: ROTEM INDUSTRIES ISRAEL LTD | E12: COSTRUTTORE | F12: APPARATI TECNOLOGIE AVANZATE | L12: ISO 9001:2015 | N12: 45443
B13: 6 | C13: A | D13: DEEP LAB S.R.L. | E13: COSTRUTTORE | F13: PROGETTAZIONE E REALIZZAZIONE MACCHINARI, PARTICOLARI MECCANICI E IMPIANTI | L13: QUESTIONARIO PRE-QUALIFICA | N13: 45447
B14: 7 | C14: A | D14: C&C S.R.L. | E14: FORNITORE A SPECIFICA | L14: EN 9100:2018 | M14: 46184 | N14: 45469
B15: 8 | C15: A | D15: AVIATRONIK TRESCAL S.p.A. | E15: DISTRIBUTORE | F15: APPARECCHIATURE ELETTRONICHE | L15: ISO 9001:2015 | M15: 46960 | N15: 45583
B16: 9 | C16: A | D16: RACK PERUZZI | E16: COSTRUTTORE | F16: COSTRUZIONE RACK | L16: ISO 9001:2015 | M16: 46351 | N16: 45614
B17: 10 | C17: A | D17: GESTIONE SILO | E17: COSTRUTTORE | F17: DISPOSITIVI OTTICI | L17: ISO 9001:2015 | M17: 46374 | N17: 45938
B18: 11 | C18: A | D18: PECCHIOLI RESEARCH S.R.L. | E18: COSTRUTTORE | F18: COMPONENTI PER SISTEMI OTTICI | L18: ISO 9001:2015 | M18: 46532 | N18: 45404
B19: 12 | C19: A | D19: TESLAB S.R.L. | F19: LABORATORIO TEST | K19: ISO 9001:2015 | M19: 45580
B20: 13 | C20: A | D20: TS2 ENGINEERING | F20: PROGETTAZIONE | K20: ISO 9001:2015

Sheet CLASSE B (built to print)
D1: REGISTRO FORNITORI QUALIFICATI TIPO B - ITEM E SERVIZI AL CLIENTE
L2: Certificato disponibile
L3: Certificazione verificata di web
L4: Certificazione verificata Accredia
L5: Certificazione scaduta - richiedere nuova
B7: POS. | C7: TIPO | D7: RAGIONE SOCIALE | E7: TIPO | F7: AMBITO DI FORNITURA | G7: CERTIFICAZIONE | H7: DISTRIBUTORE UFFICIALE O BROKER | I7: NOTE | J7: KPI QUALITA' | K7: KPI TEMPI | L7: CERTIFICAZIONI | M7: DATA SCADENZA CERTIFICAZIONE | N7: DATA INSERIMENTO | O7: INVIO CGA | P7: ACCETTAZIONE | Q7: NON ACCETTAZIONE
B8: 1 | C8: B | D8: BRUNETTI & FIGLIO S.N.C. | E8: SUBFORNITORE | F8: PROCESSI DI VERNICIATURA TRATTAMENTI GALVANICI | L8: ISO 9001:2015 | M8: 46708 | O8: SI | P8: SI
B9: 2 | C9: B | D9: CIRCUITI STAMPATI S.R.L. | E9: SUBFORNITORE | F9: CIRCUITI STAMPATI MULTISTRATO RIGIDI E PER APPLICAZIONI MICROONDE | L9: ISO 9001:2015 | M9: 46563
B10: 3 | C10: B | D10: OFFICINE LAMERA S.R.L. | E10: COSTRUTTORE | F10: MATERIALI MECCANICI | L10: ISO 9001:2015 | M10: 46849 | O10: SI
B11: 4 | C11: B | D11: TECNOMILL S.R.L. | E11: COSTRUTTORE | F11: MATERIALI MECCANICI | L11: ISO 9001:2015 / EN 9100:2018 | M11: 46183 | O11: SI
B12: 5 | C12: B | D12: MITOR SYSTEM S.R.L. | E12: COSTRUTTORE | F12: MATERIALI MECCANICI | L12: ISO 9001:2015 | M12: 46399 | O12: SI | P12: SI
B13: 6 | C13: B | D13: METATRON S.R.L. | E13: COSTRUTTORE | F13: SERIGRAFIA | L13: ISO 9001:2015 | M13: 46430 | O13: SI | P13: SI
B14: 7 | C14: B | D14: ELETTRONICA SRLS | E14: COSTRUTTORE | F14: MONTAGGIO SCHEDE ELETTRONICHE | L14: ISO 9001:2015 | M14: 45720 | O14: SI
B15: 8 | C15: B | D15: F.LLI GUERRERO S.R.L. | E15: COSTRUTTORE | F15: VERNICIATURA | L15: ISO 9001:2015 | M15: 46720 | O15: SI
B16: 9 | C16: B | D16: SHENZEN JINSHENGDA ELECTRONIC & TECH CO. | E16: COSTRUTTORE | F16: COSTRUTTORE CIRCUITI STAMPATI | L16: ISO 9001:2015 | M16: 46493
B17: 10 | C17: B | D17: ELMACOM S.R.L. | E17: COSTRUTTORE | F17: CABLAGGI | L17: ISO 9001:2015 - n.CERT-08364-2001-AQ-ROM-SINCERT
B18: 11 | C18: B | D18: ASSELTECH S.R.L. | E18: COSTRUTTORE | F18: MONTAGGIO SCHEDE ELETTRONICHE | L18: ISO 9001:2015 | M18: 46794 | O18: SI | P18: SI
B19: 12 | C19: B | D19: CML F.LLI LIBERATI SRL | E19: COSTRUTTORE | F19: LAVORAZIONI MECCANICHE | L19: ISO 9001:2015 - certificato n. IT312812
B20: 13 | C20: B | D20: ELCO S.P.A. | E20: SUBFORNITORE | F20: CIRCUITI STAMPATI MULTISTRATO RIGIDI E PER APPLICAZIONI MICROONDE | L20: ISO 9001:2015 | M20: 45620
B21: 14 | C21: B | D21: CE.CA.SA. S.R.L. | E21: COSTRUTTORE | F21: LAVORAZIONI MECCANICHE | L21: ISO 9001:2015 | M21: 46222 | O21: SI | P21: SI
B22: 15 | C22: B | D22: LA NUOVA EUROGALV S.R.L. | E22: PRODUTTORE | F22: TRATTAMENTI GALVANICI | L22: ISO 9001:2015 | M22: 46753 | O22: SI | P22: SI
B23: 16 | C23: B | D23: GALVANICA ITALIA S.R.L. | E23: PRODUTTORE | F23: TRATTAMENTI GALVANICI | L23: ISO 9001:2015 | M23: 45682 | O23: SI
B24: 17 | C24: B | D24: MECCANICA INNOVATIVA S.R.L. | E24: COSTRUTTORE | F24: LAVORAZIONI MECCANICHE | L24: ISO 9001:2015 | M24: 46307 | O24: SI | P24: SI
B25: 18 | C25: B | D25: PROVAL SERVICE S.R.L. | E25: COSTRUTTORE | F25: LAMINE SERIGRAFICHE | L25: ISO 9001:2015 | M25: 46490 | O25: SI | P25: SI
B26: 19 | C26: B | D26: EL.TREV. S.R.L. | E26: COSTRUTTORE | F26: MONTAGGIO SCHEDE ELETTRONICHE | L26: ISO 9001:2015 / EN 9100:2018 | M26: 46193 | O26: SI
B27: 20 | C27: B | D27: PROTO LABS TOOLING GmbH | E27: COSTRUTTORE | F27: STAMPAGGIO, LAVORAZIONI CNC, STAMPA 3D | L27: ISO 9001:2015 | M27: 46521 | N27: 45355 | O27: SI
B28: 21 | C28: B | D28: GENEX RF srl | E28: PRODUTTORE | F28: COMPONENTI ELETTRONICI | L28: ISO 9001:2015 - certificato n. 9170.GEN2 | N28: 45363 | O28: SI | P28: SI
B29: 22 | C29: B | D29: TRATTAMENTI GALVANICI INDUSTRIALI S.R.L. | E29: PRODUTTORE | F29: TRATTAMENTI GALVANICI | L29: ISO 9001:2015 / EN 9100:2018 | M29: 45695 | N29: 45425 | O29: SI | P29: SI
B30: 23 | C30: B | D30: SUNKING CIRCUITS ELECTRONICS CO., LTD. | E30: COSTRUTTORE | F30: CIRCUITI STAMPATI | L30: ISO 9001:2015 | M30: 45515 | N30: 45495
B31: 24 | C31: B | D31: GOAN S.R.L. | E31: COSTRUTTORE | F31: LAVORAZIONI MECCANICHE | L31: ISO 9001:2015 | M31: 46315 | N31: 45552
B32: 25 | C32: B | D32: FG MECCANICA di FABRIZI GIORGIO | E32: COSTRUTTORE | F32: LAVORAZIONI MECCANICHE | L32: QUESTIONARIO PRE-QUALIFICA in attesa approvazione Spartaco | N32: 45558
B33: 26 | C33: B | D33: MATTIOCCO ELASTOMERI S.R.L. | E33: COSTRUTTORE | F33: MATERIALI PLASTICI | L33: ISO 9001:2015 | M33: 46595 | N33: 45562
B34: 27 | C34: B | D34: TECNOMEC S.R.L. | E34: COSTRUTTORE | F34: CIRCUITI STAMPATI | L34: ISO 9001:2015 | M34: 45439 | N34: 45572
B35: 28 | C35: B | D35: CISEL S.R.L. | E35: COSTRUTTORE | F35: CIRCUITI STAMPATI | L35: ISO 9001:2015 | M35: 46591 | N35: 45572
B36: 29 | C36: B | D36: MONDO PLASTICA S.R.L. | E36: DISTRIBUTORE | F36: MATERIE PLASTICHE | L36: QUESTIONARIO PRE-QUALIFICA in attesa approvazione Spartaco | N36: 45645
B37: 30 | C37: B | D37: CISTELAIER S.p.A. | E37: COSTRUTTORE | F37: CIRCUITI STAMPATI | L37: ISO 9001:2015 / EN 9100:2018 | M37: 22/02/2027 - 03/03/2026 | N37: 45671 | O37: SI
B38: 31 | C38: B | D38: LAMECO | E38: COSTRUTTORE | F38: LAVORAZIONI MECCANICHE | L38: ISO 9001:2015 / EN 9100:2018 | M38: 46472 | N38: 45671
B39: 32 | C39: B | D39: F.C.E. S.r.l. | E39: COSTRUTTORE | F39: LAVORAZIONI MECCANICHE | L39: ISO 9001:2015 | M39: 46173 | N39: 45790
B40: 33 | C40: B | D40: ALMET ITALIA S.r.l. | E40: DISTRIBUTORE | F40: MATERIE PRIME | L40: ISO 9001:2015 | M40: 45863 | N40: 45870 | O40: SI | P40: SI
B41: 34 | C41: B | D41: ALLUMINIO DI QUALITA' | E41: DISTRIBUTORE | F41: MATERIE PRIME | L41: ISO 9001:2015 | M41: 46568 | N41: 45908
...

Sheet CLASSE C (coats)
D1: REGISTRO FORNITORI QUALIFICATI TIPO C- ITEM E SERVIZI AL CLIENTE
L2: Certificato disponibile
L3: Certificazione verificata di web
L4: Certificazione verificata Accredia
L5: Certificazione scaduta - richiedere nuova
B7: POS. | C7: TIPO | D7: RAGIONE SOCIALE | E7: TIPO | F7: AMBITO DI FORNITURA | G7: CERTIFICAZIONE | H7: DISTRIBUTORE UFFICIALE O BROKER | I7: NOTE | J7: KPI QUALITA' | K7: KPI TEMPI | L7: CERTIFICAZIONI | M7: DATA SCADENZA CERTIFICAZIONE | N7: DATA INSERIMENTO | O7: INVIO CGA | P7: ACCETTAZIONE | Q7: NON ACCETTAZIONE
B8: 1 | C8: C | D8: MILEXIA ITALIA S.P.A. | E8: DISTRIBUTORE | F8: COMPONENTI ELETTRONICI | L8: ISO 9001:2015 | M8: 46130
B9: 2 | C9: C | D9: SERVOTECNICA S.P.A. | E9: COSTRUTTORE | F9: COMPONENTI ELETTRONICI | L9: ISO 9001:2015 | M9: 46549 | O9: SI
B10: 3 | C10: C | D10: SOLYNX CORPORATION | E10: DISTRIBUTORE | F10: COMPONENTI ELETTRONICI | L10: ISO 9001:2015 | M10: 46132
B11: 4 | C11: C | D11: AVIATRONIK TRESCAL S.p.A. | E11: DISTRIBUTORE | F11: APPARECCHIATURE ELETTRONICHE | L11: ISO 9001:2015 | M11: 46960 | N11: 45583
B12: 5 | C12: C | D12: MAGI srl | E12: DISTRIBUTORE | F12: COMPONENTI MECCANICI DI PRECISIONE | L12: ISO 9001:2015 - certificato n. 1280
B13: 6 | C13: C | D13: BROWNELL LTD | E13: COSTRUTTORE | F13: PRODOTTI A CATALOGO | L13: ISO 9001:2015 | M13: 46488 | N13: 45385
B14: 7 | C14: C | D14: ACAL BFI ITALY srl | E14: DISTRIBUTORE | F14: COMPONENTI ELETTRONICI | L14: ISO 9001:2015 | M14: 46434 | N14: 45394

Sheet CLASSE D (distributori)
D1: REGISTRO FORNITORI QUALIFICATI TIPO D - ITEM E SERVIZI AL CLIENTE
L2: Certificato disponibile
L3: Certificazione verificata di web
L4: Certificazione verificata Accredia
L5: Certificazione scaduta - richiedere nuova
B7: POS. | C7: TIPO | D7: RAGIONE SOCIALE | E7: TIPO | F7: AMBITO DI FORNITURA | G7: CERTIFICAZIONE | H7: DISTRIBUTORE UFFICIALE O BROKER | I7: NOTE | J7: KPI QUALITA' | K7: KPI TEMPI | L7: CERTIFICAZIONI | M7: DATA SCADENZA CERTIFICAZIONE | N7: DATA INSERIMENTO | O7: INVIO CGA | P7: ACCETTAZIONE | Q7: NON ACCETTAZIONE
B8: 1 | C8: D | D8: MOUSER | E8: DISTRIBUTORE | F8: COMPONENTI ELETTRONICI | L8: ISO 9001-2015 / AS9100D | M8: 47004
B9: 2 | C9: D | D9: DIGI-KEY | E9: DISTRIBUTORE | F9: COMPONENTI ELETTRONICI | L9: ISO 9001:2015 | M9: 46118
B10: 3 | C10: D | D10: FARNELL ITALIA S.R.L. | E10: DISTRIBUTORE | F10: COMPONENTI ELETTRONICI | L10: ISO 9001:2015 | M10: 46682
B11: 4 | C11: D | D11: P.F. ELETTRONICA S.N.C. | E11: BROKER | F11: COMPONENTI ELETTRONICI | L11: ISO 9001:2015 | M11: 46735
B12: 5 | C12: D | D12: NICOMATIC SA | E12: COSTRUTTORE | F12: CONNETTORI | L12: ISO 9001:2015 | M12: 46181
B13: 6 | C13: D | D13: BOSSARD ITALIA S.R.L. | E13: DISTRIBUTORE | F13: DISTRIBUTORE VITERIA | L13: ISO 9001:2015 | M13: 46771
B14: 7 | C14: D | D14: AFAR S.R.L. | E14: BROKER | F14: COMPONENTI ELETTRONICI | L14: ISO 9001:2015 / EN 9120:2018 | M14: 46550
B15: 8 | C15: D | D15: LUMITRON | E15: COSTRUTTORE | F15: LED | L15: ISO 9001:2015 | M15: 46641
B16: 9 | C16: D | D16: MISUMI EUROPA GMBH | E16: DISTRIBUTORE | F16: MATERIALI MECCANICI | L16: ISO 9001:2015 | M16: 46741
B17: 10 | C17: D | D17: RS COMPONENTS S.R.L. | E17: DISTRIBUTORE | F17: COMPONENTI ELETTRONICI | L17: ISO 9001:2015 | M17: 46538
B18: 11 | C18: D | D18: ALHOF S.p.A. | E18: DISTRIBUTORE | F18: COMPONENTI ELETTROMECCANICI | L18: ISO 9001:2015 / EN 9120:2018 | M18: 46160 | N18: 45369 | O18: SI | P18: SI
B19: 12 | C19: D | D19: FUTURA S.R.L. | E19: COSTRUTTORE | F19: COMPONENTI ELETTRONICI | L19: ISO 9001:2015 | M19: 45683 | N19: 45399
B20: 13 | C20: D | D20: ELETTROLEGHE S.R.L. | E20: DISTRIBUTORE | F20: MATERIE PRIME | L20: QUESTIONARIO PRE-QUALIFICA | N20: 45421 | O20: SI | P20: SI
B21: 14 | C21: D | D21: NUOVA ITALACCIAI S.R.L. | E21: DISTRIBUTORE | F21: MATERIE PRIME | L21: QUESTIONARIO PRE-QUALIFICA | N21: 45433 | O21: SI | P21: SI
B22: 15 | C22: D | D22: J2 SOURCING AB | E22: DISTRIBUTORE | F22: COMPONENTI ELETTRONICI | L22: ISO 9001:2015 | M22: 46103 | N22: 45482
B23: 16 | C23: D | D23: DB ELECTRONIC INSTRUMENTS S.R.L. | E23: DISTRIBUTORE | F23: COMPONENTI ELETTRONICI | L23: QUESTIONARIO PRE-QUALIFICA in attesa approvazione Spartaco | N23: 45489
B24: 17 | C24: D | D24: SGA S.R.L. | E24: DISTRIBUTORE | F24: COMPONENTI ELETTRONICI | L24: ISO 9001:2015 | M24: 46809 | N24: 45489 | O24: SI | P24: SI
B25: 18 | C25: D | D25: A.B. ESSE S.P.A. | E25: COSTRUTTORE | F25: APPARECCHIATURE LASER | L25: QUESTIONARIO PRE-QUALIFICA in attesa approvazione Spartaco | N25: 45502
B26: 19 | C26: D | D26: NEXOS | E26: DISTRIBUTORE | F26: COMPONENTI ELETTRONICI | L26: QUESTIONARIO PRE-QUALIFICA in attesa approvazione Spartaco | N26: 45582
B27: 20 | C27: D | D27: PROMATEC S.p.A. | E27: DISTRIBUTORE | F27: COMPONENTI FLUIDODINAMICI | L27: ISO 9001:2015 | M27: 46702 | N27: 45607
B28: 21 | C28: D | D28: VIGO PHOTONICS S.A. | E28: COSTRUTTORE | F28: COMPONENTI ELETTRONICI | L28: ISO 9001:2015 | M28: 46921 | N28: 45644
B29: 22 | C29: D | D29: CELTE S.p.A. | E29: DISTRIBUTORE | F29: COMPONENTI ELETTRONICI | L29: ISO 9001:2015 | M29: 46802 | N29: 45673
B30: 23 | C30: D | D30: ADVAM S.R.L. | E30: DISTRIBUTORE | F30: COMPONENTI ELETTRONICI | L30: ISO 9001:2015 | M30: 45992 | N30: 45684 | O30: SI | P30: SI
B31: 24 | C31: D | D31: GLENAIR ITALIA S.p.A. | E31: PRODUTTORE | F31: COMPONENTI ELETTRONICI | L31: ISO 9001:2015 | M31: 46735 | N31: 45685
B32: 25 | C32: D | D32: SPECTROGON AB | E32: COSTRUTTORE | F32: COMPONENTI OTTICI | L32: ISO 9001:2015 | M32: 46917 | N32: 45687
B33: 26 | C33: D | D33: CONVERGE | E33: DISTRIBUTORE | F33: COMPONENTI ELETTRONICI | L33: ISO 9001:2015 | M33: 46758 | N33: 45721
B34: 27 | C34: D | D34: DIMAC RED S.p.A. | E34: DISTRIBUTORE | F34: COMPONENTI ELETTRONICI | L34: ISO 9001:2015 | M34: 46108 | N34: 45723
B35: 28 | C35: D | D35: TECHNOLOGY NUCLEAR ELECTRONICS SRL | E35: DISTRIBUTORE | F35: COMPONENTI ELETTRONICI | L35: ISO 9001:2015 - certificato n. 9115.TNE1 | N35: 45729
B36: 29 | C36: D | D36: PLABER | E36: COSTRUTTORE | N36: 45741
B37: 30 | C37: D | D37: ELESA S.p.A. | E37: PRODUTTORE | F37: COMPONENTI INDUSTRIALI | L37: ISO 9001:2015 | M37: 46846 | N37: 45761
B38: 31 | C38: D | D38: Microchip Technology Ireland Ltd. | E38: DISTRIBUTORI | F38: COMPONENTI ELETTRONICI | L38: ISO 9001:2015 | M38: 46536 | N38: 45802
B39: 32 | C39: D | D39: ARROW ELECTRONICS INC | E39: DISTRIBUTORE | F39: COMPONENTI ELETTRONICI | L39: ISO 9001:2015 | M39: 46068 | N39: 45812
B40: 33 | C40: D | D40: CONRAD ELECTRONIC ITALIA S.r.l. | E40: DISTRIBUTORE | F40: COMPONENTI ELETTRONICI | L40: ISO 9001:2015 | M40: 46773 | N40: 45859
B41: 34 | C41: D | D41: SAMTEC | E41: DISTRIBUTORE | F41: COMPONENTI ELETTRONICI | L41: ISO 9001:2015 | M41: 46371 | N41: 45925
...

Sheet CLASSE E (generali stabilimento
D1: REGISTRO FORNITORI QUALIFICATI TIPO E - ITEM E SERVIZI AL CLIENTE
L2: Certificato disponibile
L3: Certificazione verificata di web
L4: Certificazione verificata Accredia
L5: Certificazione scaduta - richiedere nuova
B7: POS. | C7: TIPO | D7: RAGIONE SOCIALE | E7: TIPO | F7: AMBITO DI FORNITURA | G7: CERTIFICAZIONE | H7: DISTRIBUTORE UFFICIALE O BROKER | I7: NOTE | J7: KPI QUALITA' | K7: KPI TEMPI | L7: CERTIFICAZIONI | M7: DATA SCADENZA CERTIFICAZIONE | N7: DATA INSERIMENTO | O7: INVIO CGA | P7: ACCETTAZIONE | Q7: NON ACCETTAZIONE
B9: 1 | C9: E | D9: MONDOFFICE | E9: DISTRIBUTORE | F9: CARTOLERIA, MATERIALI PER UFFICI
B10: 2 | C10: E | D10: LIBER S.R.L. | E10: PRODUTTORE | F10: PRODOTTI PER PULIZIA
B11: 3 | C11: E | D11: E.S.E. GEA S.R.L. | E11: SERVIZI | F11: MANUTENZIONE FABBRICATI
B12: 4 | C12: E | D12: FENICE MULTISERVIZI S.R.L. | E12: SERVIZI | F12: PULIZIA, SFALCIO ERBA, FACCHINAGGIO
B13: 5 | C13: E | D13: AIRSERVICE S.R.L. | E13: ASSISTENZA TECNICA | F13: INSTALLAZIONE E ASSISTENZA IMPIANTI TECNOLOGICI
B14: 6 | C14: E | D14: CATAPANO MAURO | E14: LIBERO PROFESSIONISTA | F14: ASSISTENZA IMPIANTI IDRAULICI
B15: 7 | C15: E | D15: TECNOCLIMA S.R.L. | E15: ASSISTENZA TECNICA | F15: MANUTENZIONE IMPIANTI
B16: 8 | C16: E | D16: HSC | E16: DISTRIBUTORE | F16: PRODOTTI VARI PER AZIENDE (PULIZIA / IMBALLAGGIO / ANTINFORTUNISTICA)
B17: 9 | C17: E | D17: ANTINCENDIO 2005 | E17: SERVIZI | F17: ANTINCENDIO, MANUTENZIONE ESTINTORI
B18: 10 | C18: E | D18: PRAGMA | E18: SERVIZI | F18: SMALTIMENTO RIFIUTI
B19: 11 | C19: E | D19: PRAXIGROUP | E19: SERVIZI | F19: MEDICO COMPETENTE
B20: 12 | C20: E | D20: TECNO GENERAL | E20: SERVIZI | F20: TELEFONIA, INTERNET
... B33: 25 | C33: E | D33: AMINSTRUMENTS | E33: PRODUTTORE | F33: PRODOTTI E SERVIZI ESD / CLEAN ROOM
B34: 26 | C34: E | D34: CABIOTEC S.R.L. | E34: DISTRIBUTORE | F34: Materiali di consumo per il montaggio superficiale (SMT) e tradizionale di schede elettroniche. | K34: ISO 9001:2015 - certificato n. 60506 | N34: SI
B35: 27 | C35: E | D35: ANGELANTONI TEST TECHNOLOGIES S.R.L. | E35: PRODUTTORE | F35: SIMULAZIONI - CALIBRAZIONI | K35: ISO 9001:2015
B36: 28 | C36: E | D36: MARGARINI IMBALLI S.r.l. | E36: COSTRUTTORE | F36: IMBALLI A DISEGNO | L36: inviato QUESTIONARIO PREQUALIFICA | N36: 45806
B37: 29 | C37: E | D37: BERNER | F37: PRODOTTI VARI PER PRODUZIONE
B38: 30 | C38: E | D38: CDP | E38: SERVIZI | F38: TIPOGRAFIA
B39: 31 | C39: E | D39: HOFFMANN | E39: DISTRIBUTORE | F39: UTENSILERIA E PRODOTTI PER OFFICINA
B40: 32 | C40: E | D40: GENERAL COMPUTER | E40: DISTRIBUTORE | F40: PRODOTTI HARDWARE E LICENZE SOFTWARE
B41: 33 | C41: E | D41: DATAONE | E41: DISTRIBUTORE | F41: LICENZE SOFTWARE
B42: 34 | C42: E | D42: BELOTTI SISTEMI | E42: DISTRIBUTORE
B43: 35 | C43: E | D43: WETEC | E43: DISTRIBUTORE

Sheet NON UTILIZZATI (>2 ANNI)
D1: REGISTRO FORNITORI QUALIFICATI TIPO F - ITEM E SERVIZI AL CLIENTE
L2: Certificato disponibile
L3: Certificazione verificata di web
L4: Certificazione verificata Accredia
L5: Certificazione scaduta - richiedere nuova
B7: POS. | C7: TIPO | D7: RAGIONE SOCIALE | E7: TIPO | F7: AMBITO DI FORNITURA | G7: CERTIFICAZIONE | H7: DISTRIBUTORE UFFICIALE O BROKER | I7: NOTE | J7: KPI QUALITA' | K7: KPI TEMPI | L7: CERTIFICAZIONI | M7: DATA SCADENZA CERTIFICAZIONE | N7: DATA INSERIMENTO | O7: INVIO CGA | P7: ACCETTAZIONE | Q7: NON ACCETTAZIONE
B9: 24 | C9: B | D9: ELETTRONICA SRLS | E9: COSTRUTTORE | F9: MONTAGGIO SCHEDE ELETTRONICHE | L9: ISO 9001:2015 | M9: 45720 | O9: SI

Sheet SEPARAZIONE SHEET OLD

Sheet ITEM E SERVIZI AL CLIENTE
D1: REGISTRO FORNITORI QUALIFICATI - ITEM E SERVIZI AL CLIENTE
L2: Certificato disponibile
L3: Certificazione verificata di web
L4: Certificazione verificata Accredia
L5: Certificazione scaduta - richiedere nuova
B7: POS. | C7: TIPO | D7: RAGIONE SOCIALE | E7: TIPO | F7: AMBITO DI FORNITURA | G7: CERTIFICAZIONE | H7: DISTRIBUTORE UFFICIALE O BROKER | I7: NOTE | J7: KPI QUALITA' | K7: KPI TEMPI | L7: CERTIFICAZIONI | M7: DATA SCADENZA CERTIFICAZIONE | N7: DATA INSERIMENTO | O7: INVIO CGA | P7: ACCETTAZIONE | Q7: NON ACCETTAZIONE
B8: 1 | C8: B | D8: BRUNETTI & FIGLIO S.N.C. | E8: SUBFORNITORE | F8: PROCESSI DI VERNICIATURA TRATTAMENTI GALVANICI | L8: ISO 9001:2015 | M8: 46708 | O8: SI | P8: SI
B9: 2 | C9: B | D9: CIRCUITI STAMPATI S.R.L. | E9: SUBFORNITORE | F9: CIRCUITI STAMPATI MULTISTRATO RIGIDI E PER APPLICAZIONI MICROONDE | L9: ISO 9001:2015 | M9: 46563
B10: 3 | C10: A | D10: D & P Electronic Systems Srl | E10: FORNITORE A SPECIFICA | F10: PROGETTAZIONE HW/SW, SVILUPPO DOCUMENTAZIONE E FORNITURA SCHEDE DIGITALI | L10: ISO 9001:2015 - certificato n. 12963
B11: 7 | C11: D | D11: MOUSER | E11: DISTRIBUTORE | F11: COMPONENTI ELETTRONICI | L11: ISO 9001-2015 / AS9100D | M11: 47004
B12: 8 | C12: D | D12: DIGI-KEY | E12: DISTRIBUTORE | F12: COMPONENTI ELETTRONICI | L12: ISO 9001:2015 | M12: 46118
B13: 9 | C13: D | D13: FARNELL ITALIA S.R.L. | E13: DISTRIBUTORE | F13: COMPONENTI ELETTRONICI | L13: ISO 9001:2015 | M13: 46682
B14: 10 | C14: D | D14: P.F. ELETTRONICA S.N.C. | E14: BROKER | F14: COMPONENTI ELETTRONICI | L14: ISO 9001:2015 | M14: 46735
B15: 11 | C15: D | D15: NICOMATIC SA | E15: COSTRUTTORE | F15: CONNETTORI | L15: ISO 9001:2015 | M15: 46181
B16: 12 | C16: C | D16: MILEXIA ITALIA S.P.A. | E16: DISTRIBUTORE | F16: COMPONENTI ELETTRONICI | L16: ISO 9001:2015 | M16: 46130
B17: 13 | C17: C | D17: SERVOTECNICA S.P.A. | E17: COSTRUTTORE | F17: COMPONENTI ELETTRONICI | L17: ISO 9001:2015 | M17: 46549 | O17: SI
B18: 14 | C18: D | D18: BOSSARD ITALIA S.R.L. | E18: DISTRIBUTORE | F18: DISTRIBUTORE VITERIA | L18: ISO 9001:2015 | M18: 46771
B19: 15 | C19: D | D19: MAGI srl | E19: DISTRIBUTORE | F19: COMPONENTI MECCANICI DI PRECISIONE | L19: ISO 9001:2015 - certificato n. 1280
B20: 16 | C20: B | D20: OFFICINE LAMERA S.R.L. | E20: COSTRUTTORE | F20: MATERIALI MECCANICI | L20: ISO 9001:2015 | M20: 46849 | O20: SI
B21: 17 | C21: B | D21: TECNOMILL S.R.L. | E21: COSTRUTTORE | F21: MATERIALI MECCANICI | L21: ISO 9001:2015 / EN 9100:2018 | M21: 46183 | O21: SI
B22: 18 | C22: B | D22: MITOR SYSTEM S.R.L. | E22: COSTRUTTORE | F22: MATERIALI MECCANICI | L22: ISO 9001:2015 | M22: 46399 | O22: SI | P22: SI
B23: 19 | C23: D | D23: AFAR S.R.L. | E23: BROKER | F23: COMPONENTI ELETTRONICI | L23: ISO 9001:2015 / EN 9120:2018 | M23: 46550
B24: 23 | C24: B | D24: METATRON S.R.L. | E24: COSTRUTTORE | F24: SERIGRAFIA | L24: ISO 9001:2015 | M24: 46430 | O24: SI | P24: SI
B25: 24 | C25: B | D25: ELETTRONICA SRLS | E25: COSTRUTTORE | F25: MONTAGGIO SCHEDE ELETTRONICHE | L25: ISO 9001:2015 | M25: 45720 | O25: SI
B26: 25 | C26: B | D26: F.LLI GUERRERO S.R.L. | E26: COSTRUTTORE | F26: VERNICIATURA | L26: ISO 9001:2015 | M26: 46720 | O26: SI
B27: 26 | C27: B | D27: SHENZEN JINSHENGDA ELECTRONIC & TECH CO. | E27: COSTRUTTORE | F27: COSTRUTTORE CIRCUITI STAMPATI | L27: ISO 9001:2015 | M27: 46493
B28: 28 | C28: B | D28: ELMACOM S.R.L. | E28: COSTRUTTORE | F28: CABLAGGI | L28: ISO 9001:2015 - n.CERT-08364-2001-AQ-ROM-SINCERT
B29: 29 | C29: B | D29: ASSELTECH S.R.L. | E29: COSTRUTTORE | F29: MONTAGGIO SCHEDE ELETTRONICHE | L29: ISO 9001:2015 | M29: 46794 | O29: SI | P29: SI
B30: 30 | C30: D | D30: LUMITRON | E30: COSTRUTTORE | F30: LED | L30: ISO 9001:2015 | M30: 46641
B31: 34 | C31: B | D31: CML F.LLI LIBERATI SRL | E31: COSTRUTTORE | F31: LAVORAZIONI MECCANICHE | L31: ISO 9001:2015 - certificato n. IT312812
B32: 38 | C32: D | D32: MISUMI EUROPA GMBH | E32: DISTRIBUTORE | F32: MATERIALI MECCANICI | L32: ISO 9001:2015 | M32: 46741
B33: 39 | C33: B | D33: ELCO S.P.A. | E33: SUBFORNITORE | F33: CIRCUITI STAMPATI MULTISTRATO RIGIDI E PER APPLICAZIONI MICROONDE | L33: ISO 9001:2015 | M33: 45620
B34: 41 | C34: B | D34: CE.CA.SA. S.R.L. | E34: COSTRUTTORE | F34: LAVORAZIONI MECCANICHE | L34: ISO 9001:2015 | M34: 46222 | O34: SI | P34: SI
B35: 42 | C35: B | D35: LA NUOVA EUROGALV S.R.L. | E35: PRODUTTORE | F35: TRATTAMENTI GALVANICI | L35: ISO 9001:2015 | M35: 46753 | O35: SI | P35: SI
B36: 43 | C36: B | D36: GALVANICA ITALIA S.R.L. | E36: PRODUTTORE | F36: TRATTAMENTI GALVANICI | L36: ISO 9001:2015 | M36: 45682 | O36: SI
B37: 44 | C37: B | D37: MECCANICA INNOVATIVA S.R.L. | E37: COSTRUTTORE | F37: LAVORAZIONI MECCANICHE | L37: ISO 9001:2015 | M37: 46307 | O37: SI | P37: SI
B38: 45 | C38: B | D38: PROVAL SERVICE S.R.L. | E38: COSTRUTTORE | F38: LAMINE SERIGRAFICHE | L38: ISO 9001:2015 | M38: 46490 | O38: SI | P38: SI
B39: 46 | C39: D | D39: RS COMPONENTS S.R.L. | E39: DISTRIBUTORE | F39: COMPONENTI ELETTRONICI | L39: ISO 9001:2015 | M39: 46538
B40: 47 | C40: B | D40: EL.TREV. S.R.L. | E40: COSTRUTTORE | F40: MONTAGGIO SCHEDE ELETTRONICHE | L40: ISO 9001:2015 / EN 9100:2018 | M40: 46193 | O40: SI
B41: 48 | C41: A | D41: PARIANI S.R.L. | E41: COSTRUTTORE | F41: SISTEMI DI ILLUMINAZIONE | L41: ISO 9001:2015 | M41: 45538 | O41: SI
...

Sheet ITEM E SERVIZI INTERNI
C1: REGISTRO FORNITORI QUALIFICATI - ITEM E SERVIZI INTERNI
K2: Certificato disponibile
K3: Certificazione verificata di web
K4: Certificazione verificata Accredia
C6: RAGIONE SOCIALE | D6: TIPO | E6: AMBITO DI FORNITURA | F6: CERTIFICAZIONE | G6: DISTRIBUTORE UFFICIALE O BROKER | H6: NOTE | I6: KPI QUALITA' | J6: KPI TEMPI | K6: CERTIFICAZIONI | L6: DATA INSERIMENTO | M6: INVIO CGA | N6: ACCETTAZIONE | O6: NON ACCETTAZIONE
B7: 1 | C7: E.S.E. GEA S.R.L. | D7: SERVIZI | E7: MANUTENZIONE FABBRICATI
B8: 2 | C8: FENICE MULTISERVIZI S.R.L. | D8: SERVIZI | E8: PULIZIA, SFALCIO ERBA, FACCHINAGGIO
B9: 3 | C9: AIRSERVICE S.R.L. | D9: ASSISTENZA TECNICA | E9: INSTALLAZIONE E ASSISTENZA IMPIANTI TECNOLOGICI
B10: 4 | C10: CATAPANO MAURO | D10: LIBERO PROFESSIONISTA | E10: ASSISTENZA IMPIANTI IDRAULICI
B11: 5 | C11: TECNOCLIMA S.R.L. | D11: ASSISTENZA TECNICA | E11: MANUTENZIONE IMPIANTI
B12: 6 | C12: LIBER S.R.L. | D12: PRODUTTORE | E12: PRODOTTI PER PULIZIA
B13: 7 | C13: HSC | D13: DISTRIBUTORE | E13: PRODOTTI VARI PER AZIENDE (PULIZIA / IMBALLAGGIO / ANTINFORTUNISTICA)
B14: 8 | C14: GENERAL COMPUTER | D14: DISTRIBUTORE | E14: PRODOTTI HARDWARE E LICENZE SOFTWARE
B15: 9 | C15: ANTINCENDIO 2005 | D15: SERVIZI | E15: ANTINCENDIO, MANUTENZIONE ESTINTORI
B16: 10 | C16: CSA TEAM S.R.L. | D16: CONSULENTE | E16: SICUREZZA NEI LUOGHI DI LAVORO
B17: 11 | C17: DATAONE | D17: DISTRIBUTORE | E17: LICENZE SOFTWARE
B18: 12 | C18: ETMAN | D18: CONSULENTE | E18: CERTIFICAZIONE 14001 E SA8000
... B27: 21 | C27: TECNO GENERAL | D27: SERVIZI | E27: TELEFONIA, INTERNET
B28: 22 | C28: 1855 | D28: DISTRIBUTORE | E28: FORNITURA CAFFE'
B29: 23 | C29: BERNER | E29: PRODOTTI VARI PER PRODUZIONE
B30: 24 | C30: CDP | D30: SERVIZI | E30: TIPOGRAFIA
B31: 25 | C31: HOFFMANN | D31: DISTRIBUTORE | E31: UTENSILERIA E PRODOTTI PER OFFICINA
B32: 26 | C32: MASSARO | D32: LIBERO PROFESSIONISTA | E32: ASSISTENZA CALDAIE
B33: 27 | C33: MITUTOYO | D33: COSTRUTTORE | E33: STRUMENTI DI MISURA
B34: 28 | C34: MAZAK | D34: ASSISTENZA TECNICA | E34: VENDITA E MANUTENZIONE MACCHINE UTENSILI
B35: 29 | C35: NEXT04 | D35: SERVIZI | E35: SERVIZI INFORMATICI
B36: 30 | C36: QUASER | D36: DISTRIBUTORE | E36: PRODOTTI ESD / CLEAN ROOM
B37: 31 | C37: COMELEC S.R.L. | D37: DISTRIBUTORE
B38: 32 | C38: D.P.I. | D38: DISTRIBUTORE | E38: PRODOTTI CHIMICI (VIGON)
B39: 33 | C39: BARBIERI S.R.L. | D39: DISTRIBUTORE | E39: PRODOTTI CHIMICI (ALPHA)
B40: 34 | C40: GENTILE MULTISERVIZI | D40: SERVIZI | E40: PULIZIA AREE VERDI
B41: 35 | C41: AMINSTRUMENTS | D41: PRODUTTORE | E41: PRODOTTI E SERVIZI ESD / CLEAN ROOM
B42: 37 | C42: PARTELLI | D42: DISTRIBUTORE | E42: ATTREZZATURE OTTICHE | M42: SI
B43: 38 | C43: LASER OPTRONIC | D43: DISTRIBUTORE | E43: ATTREZZATURE OTTICHE
B44: 39 | C44: MITEC | D44: DISTRIBUTORE
B45: 40 | C45: BELOTTI SISTEMI | D45: DISTRIBUTORE
B46: 41 | C46: D.S.A | D46: DISTRIBUTORE
B47: 42 | C47: WETEC | D47: DISTRIBUTORE
B48: 43 | C48: CABIOTEC S.R.L. | D48: DISTRIBUTORE | E48: Materiali di consumo per il montaggio superficiale (SMT) e tradizionale di schede elettroniche. | K48: ISO 9001:2015 - certificato n. 60506 | N48: SI
B49: 44 | C49: ANGELANTONI TEST TECHNOLOGIES S.R.L. | D49: PRODUTTORE | E49: SIMULAZIONI - CALIBRAZIONI | K49: ISO 9001:2015
...

Sheet FORNITORI IN VALUTAZIONE
D1: REGISTRO FORNITORI QUALIFICATI - ITEM E SERVIZI AL CLIENTE
B7: POS. | C7: TIPO | D7: RAGIONE SOCIALE | E7: TIPO | F7: AMBITO DI FORNITURA | G7: CERTIFICAZIONE | H7: DISTRIBUTORE UFFICIALE O BROKER | I7: NOTE | J7: KPI QUALITA' | K7: KPI TEMPI | L7: CERTIFICAZIONI | M7: DATA SCADENZA CERTIFICAZIONE | N7: DATA INSERIMENTO | O7: INVIO CGA | P7: ACCETTAZIONE | Q7: NON ACCETTAZIONE
B8: 104 | C8: C | D8: SENRING ELECTRONICS Co. Limited | E8: COSTRUTTORE | F8: COMPONENTI ELETTRONICI | L8: ???

Sheet STORICO
D1: REGISTRO FORNITORI QUALIFICATI - ITEM E SERVIZI AL CLIENTE
L2: Certificato disponibile
L3: Certificazione verificata di web
L4: Certificazione verificata Accredia
B7: POS. | C7: TIPO | D7: RAGIONE SOCIALE | E7: TIPO | F7: AMBITO DI FORNITURA | G7: CERTIFICAZIONE | H7: DISTRIBUTORE UFFICIALE O BROKER | I7: NOTE | J7: KPI QUALITA' | K7: KPI TEMPI | L7: CERTIFICAZIONI | M7: DATA SCADENZA CERTIFICAZIONE | N7: DATA INSERIMENTO | O7: INVIO CGA | P7: ACCETTAZIONE | Q7: NON ACCETTAZIONE
B8: 1 | D8: W.L. GORE & ASSOCIATES (UK) LTD | E8: FORNITORE A CATALOGO | F8: PROGETTAZIONE, SVILUPPO E PRODUZIONE DI GUARNIZIONI E CAVI | L8: AS9100D / ISO 9001_2015
B9: 2 | D9: TTI ITALY Srl | E9: DISTRIBUTORE | F9: COMPONENTI ELETTRONICI | L9: ISO 9001:2015 / EN 9100:2018
B10: 3 | D10: TRANS-PART SRL | E10: BROKER | F10: COMPONENTI ELETTRONICI | L10: EN 9120-2018 / ISO 9001:2015
B11: 4 | C11: D | D11: A. PONTECORVO S.P.A. | E11: DISTRIBUTORE | F11: MATERIE PRIME | L11: ISO 9001:2015 | O11: SI
B12: 5 | D12: ALANTYS TECHNOLOGY | E12: BROKER | F12: COMPONENTI ELETTRONICI | L12: ISO 9001:2015
B13: 6 | D13: TECNO 77 | E13: COSTRUTTORE | F13: Master per circuiti stampati Assemblaggio schede | L13: ISO 9001:2015
B14: 7 | D14: ABIS CIRCUITS CO. LIMITED | E14: COSTRUTTORE | F14: COSTRUTTORE CIRCUITI STAMPATI | L14: ISO 9001:2015
B15: 8 | D15: CONTRADATA | E15: DISTRIBUTORE | F15: PC INDUSTRIALI | L15: ISO 9001:2015
B16: 9 | D16: GENERON SPA | E16: COSTRUTTORE | F16: STRUMENTAZIONI | L16: ISO 9001:2015 - n.CERT-17841-2006-AQ-BOL
B17: 10 | D17: TEKCELEO | E17: COSTRUTTORE | F17: STRUMENTAZIONI | L17: ISO 9001:2015
B18: 11 | D18: IPP | E18: DISTRIBUTORI | F18: Forniture Industriali per Elettronica | L18: ISO 9001:2015
B19: 10 | C19: D | D19: DISTRELEC ITALIA S.R.L. | E19: DISTRIBUTORE | F19: COMPONENTI ELETTRONICI | L19: ISO 9001:2015
